<?xml version="1.0"?>
<robot name="planar_arm">

  <!-- Base link: fixed cylinder at origin -->
  <link name="base_link">
    <inertial>
      <mass value="1.0"/>
      <inertia ixx="0.01" ixy="0" ixz="0" iyy="0.01" iyz="0" izz="0.01"/>
    </inertial>
    <visual>
      <origin xyz="0 0 0.025" rpy="0 0 0"/>
      <geometry><cylinder radius="0.07" length="0.05"/></geometry>
      <material name="dark"><color rgba="0.15 0.15 0.15 1"/></material>
    </visual>
  </link>

  <!-- Joint 1: revolute around Z at base -->
  <joint name="joint_1" type="revolute">
    <parent link="base_link"/>
    <child link="link_1"/>
    <origin xyz="0 0 0.05" rpy="0 0 0"/>
    <axis xyz="0 0 1"/>
    <limit lower="-3.14159" upper="3.14159" effort="100" velocity="3.0"/>
    <dynamics damping="0.5" friction="0.1"/>
  </joint>

  <!-- Link 1: 1.2 m, extends along +Y when joint_1 = 0 -->
  <link name="link_1">
    <inertial>
      <mass value="0.5"/>
      <inertia ixx="0.06" ixy="0" ixz="0" iyy="0.001" iyz="0" izz="0.06"/>
    </inertial>
    <visual>
      <origin xyz="0 0.6 0" rpy="0 0 0"/>
      <geometry><cylinder radius="0.045" length="1.2"/></geometry>
      <material name="steel_blue"><color rgba="0.25 0.45 0.75 1"/></material>
    </visual>
  </link>

  <!-- Joint 2: revolute around Z at end of link_1 -->
  <joint name="joint_2" type="revolute">
    <parent link="link_1"/>
    <child link="link_2"/>
    <origin xyz="0 1.2 0" rpy="0 0 0"/>
    <axis xyz="0 0 1"/>
    <limit lower="-3.14159" upper="3.14159" effort="100" velocity="3.0"/>
    <dynamics damping="0.5" friction="0.1"/>
  </joint>

  <!-- Link 2: 1.0 m -->
  <link name="link_2">
    <inertial>
      <mass value="0.3"/>
      <inertia ixx="0.025" ixy="0" ixz="0" iyy="0.001" iyz="0" izz="0.025"/>
    </inertial>
    <visual>
      <origin xyz="0 0.5 0" rpy="0 0 0"/>
      <geometry><cylinder radius="0.035" length="1.0"/></geometry>
      <material name="light_blue"><color rgba="0.45 0.65 0.90 1"/></material>
    </visual>
  </link>

  <!-- End-effector joint: fixed at tip of link_2 -->
  <joint name="ee_joint" type="fixed">
    <parent link="link_2"/>
    <child link="end_effector"/>
    <origin xyz="0 1.0 0" rpy="0 0 0"/>
  </joint>

  <!-- End effector: sphere gripper marker -->
  <link name="end_effector">
    <inertial>
      <mass value="0.05"/>
      <inertia ixx="0.0001" ixy="0" ixz="0" iyy="0.0001" iyz="0" izz="0.0001"/>
    </inertial>
    <visual>
      <geometry><sphere radius="0.07"/></geometry>
      <material name="gripper_red"><color rgba="0.9 0.2 0.15 1"/></material>
    </visual>
  </link>

</robot>
